2025-09-01 13:08:22,878 INFO    MainThread:345772 [wandb_setup.py:_flush():81] Current SDK version is 0.21.3
2025-09-01 13:08:22,878 INFO    MainThread:345772 [wandb_setup.py:_flush():81] Configure stats pid to 345772
2025-09-01 13:08:22,878 INFO    MainThread:345772 [wandb_setup.py:_flush():81] Loading settings from /zfsauton2/home/shrinivr/.config/wandb/settings
2025-09-01 13:08:22,879 INFO    MainThread:345772 [wandb_setup.py:_flush():81] Loading settings from /zfsauton2/home/shrinivr/10-623/hw0/handout/wandb/settings
2025-09-01 13:08:22,879 INFO    MainThread:345772 [wandb_setup.py:_flush():81] Loading settings from environment variables
2025-09-01 13:08:22,879 INFO    MainThread:345772 [wandb_init.py:setup_run_log_directory():686] Logging user logs to /zfsauton2/home/shrinivr/10-623/hw0/handout/wandb/run-20250901_130822-s5wpykot/logs/debug.log
2025-09-01 13:08:22,880 INFO    MainThread:345772 [wandb_init.py:setup_run_log_directory():687] Logging internal logs to /zfsauton2/home/shrinivr/10-623/hw0/handout/wandb/run-20250901_130822-s5wpykot/logs/debug-internal.log
2025-09-01 13:08:22,880 INFO    MainThread:345772 [wandb_init.py:init():813] calling init triggers
2025-09-01 13:08:22,881 INFO    MainThread:345772 [wandb_init.py:init():818] wandb.init called with sweep_config: {}
config: {'model': 'simple', 'batch_size': 8, 'learning_rate': 0.001, 'n_epochs': 5, 'grayscale': False, 'use_wandb': True, '_wandb': {'code_path': 'code/hw0/handout/img_classifier.py'}}
2025-09-01 13:08:22,881 INFO    MainThread:345772 [wandb_init.py:init():854] starting backend
2025-09-01 13:08:23,089 INFO    MainThread:345772 [wandb_init.py:init():857] sending inform_init request
2025-09-01 13:08:23,093 INFO    MainThread:345772 [wandb_init.py:init():865] backend started and connected
2025-09-01 13:08:23,095 INFO    MainThread:345772 [wandb_init.py:init():936] updated telemetry
2025-09-01 13:08:23,103 INFO    MainThread:345772 [wandb_init.py:init():960] communicating run to backend with 90.0 second timeout
2025-09-01 13:08:23,588 INFO    MainThread:345772 [wandb_init.py:init():1011] starting run threads in backend
2025-09-01 13:08:23,638 INFO    MainThread:345772 [wandb_run.py:_console_start():2494] atexit reg
2025-09-01 13:08:23,638 INFO    MainThread:345772 [wandb_run.py:_redirect():2342] redirect: wrap_raw
2025-09-01 13:08:23,639 INFO    MainThread:345772 [wandb_run.py:_redirect():2411] Wrapping output streams.
2025-09-01 13:08:23,639 INFO    MainThread:345772 [wandb_run.py:_redirect():2434] Redirects installed.
2025-09-01 13:08:23,641 INFO    MainThread:345772 [wandb_init.py:init():1057] run started, returning control to user process
2025-09-01 13:09:07,933 INFO    wandb-AsyncioManager-main:345772 [service_client.py:_forward_responses():84] Reached EOF.
2025-09-01 13:09:07,934 INFO    wandb-AsyncioManager-main:345772 [mailbox.py:close():137] Closing mailbox, abandoning 1 handles.
2025-09-01 13:09:08,458 ERROR   wandb-AsyncioManager-main:345772 [asyncio_manager.py:fn_wrap_exceptions():183] Uncaught exception in run_soon callback.
Traceback (most recent call last):
  File "/zfsauton2/home/shrinivr/miniconda3/envs/py312/lib/python3.12/site-packages/wandb/sdk/lib/asyncio_manager.py", line 181, in fn_wrap_exceptions
    await fn()
  File "/zfsauton2/home/shrinivr/miniconda3/envs/py312/lib/python3.12/site-packages/wandb/sdk/lib/service/service_client.py", line 65, in _send_server_request
    await self._writer.drain()
  File "/zfsauton2/home/shrinivr/miniconda3/envs/py312/lib/python3.12/asyncio/streams.py", line 392, in drain
    await self._protocol._drain_helper()
  File "/zfsauton2/home/shrinivr/miniconda3/envs/py312/lib/python3.12/asyncio/streams.py", line 166, in _drain_helper
    raise ConnectionResetError('Connection lost')
ConnectionResetError: Connection lost
2025-09-01 13:09:08,462 ERROR   wandb-AsyncioManager-main:345772 [asyncio_manager.py:fn_wrap_exceptions():183] Uncaught exception in run_soon callback.
Traceback (most recent call last):
  File "/zfsauton2/home/shrinivr/miniconda3/envs/py312/lib/python3.12/site-packages/wandb/sdk/lib/asyncio_manager.py", line 181, in fn_wrap_exceptions
    await fn()
  File "/zfsauton2/home/shrinivr/miniconda3/envs/py312/lib/python3.12/site-packages/wandb/sdk/lib/service/service_client.py", line 65, in _send_server_request
    await self._writer.drain()
  File "/zfsauton2/home/shrinivr/miniconda3/envs/py312/lib/python3.12/asyncio/streams.py", line 392, in drain
    await self._protocol._drain_helper()
  File "/zfsauton2/home/shrinivr/miniconda3/envs/py312/lib/python3.12/asyncio/streams.py", line 166, in _drain_helper
    raise ConnectionResetError('Connection lost')
ConnectionResetError: Connection lost
2025-09-01 13:09:08,463 ERROR   wandb-AsyncioManager-main:345772 [asyncio_manager.py:fn_wrap_exceptions():183] Uncaught exception in run_soon callback.
Traceback (most recent call last):
  File "/zfsauton2/home/shrinivr/miniconda3/envs/py312/lib/python3.12/site-packages/wandb/sdk/lib/asyncio_manager.py", line 181, in fn_wrap_exceptions
    await fn()
  File "/zfsauton2/home/shrinivr/miniconda3/envs/py312/lib/python3.12/site-packages/wandb/sdk/lib/service/service_client.py", line 65, in _send_server_request
    await self._writer.drain()
  File "/zfsauton2/home/shrinivr/miniconda3/envs/py312/lib/python3.12/asyncio/streams.py", line 392, in drain
    await self._protocol._drain_helper()
  File "/zfsauton2/home/shrinivr/miniconda3/envs/py312/lib/python3.12/asyncio/streams.py", line 166, in _drain_helper
    raise ConnectionResetError('Connection lost')
ConnectionResetError: Connection lost
2025-09-01 13:09:08,467 ERROR   wandb-AsyncioManager-main:345772 [asyncio_manager.py:fn_wrap_exceptions():183] Uncaught exception in run_soon callback.
Traceback (most recent call last):
  File "/zfsauton2/home/shrinivr/miniconda3/envs/py312/lib/python3.12/site-packages/wandb/sdk/lib/asyncio_manager.py", line 181, in fn_wrap_exceptions
    await fn()
  File "/zfsauton2/home/shrinivr/miniconda3/envs/py312/lib/python3.12/site-packages/wandb/sdk/lib/service/service_client.py", line 65, in _send_server_request
    await self._writer.drain()
  File "/zfsauton2/home/shrinivr/miniconda3/envs/py312/lib/python3.12/asyncio/streams.py", line 392, in drain
    await self._protocol._drain_helper()
  File "/zfsauton2/home/shrinivr/miniconda3/envs/py312/lib/python3.12/asyncio/streams.py", line 166, in _drain_helper
    raise ConnectionResetError('Connection lost')
ConnectionResetError: Connection lost
2025-09-01 13:09:08,467 ERROR   wandb-AsyncioManager-main:345772 [asyncio_manager.py:fn_wrap_exceptions():183] Uncaught exception in run_soon callback.
Traceback (most recent call last):
  File "/zfsauton2/home/shrinivr/miniconda3/envs/py312/lib/python3.12/site-packages/wandb/sdk/lib/asyncio_manager.py", line 181, in fn_wrap_exceptions
    await fn()
  File "/zfsauton2/home/shrinivr/miniconda3/envs/py312/lib/python3.12/site-packages/wandb/sdk/lib/service/service_client.py", line 65, in _send_server_request
    await self._writer.drain()
  File "/zfsauton2/home/shrinivr/miniconda3/envs/py312/lib/python3.12/asyncio/streams.py", line 392, in drain
    await self._protocol._drain_helper()
  File "/zfsauton2/home/shrinivr/miniconda3/envs/py312/lib/python3.12/asyncio/streams.py", line 166, in _drain_helper
    raise ConnectionResetError('Connection lost')
ConnectionResetError: Connection lost
2025-09-01 13:09:08,469 ERROR   wandb-AsyncioManager-main:345772 [asyncio_manager.py:fn_wrap_exceptions():183] Uncaught exception in run_soon callback.
Traceback (most recent call last):
  File "/zfsauton2/home/shrinivr/miniconda3/envs/py312/lib/python3.12/site-packages/wandb/sdk/lib/asyncio_manager.py", line 181, in fn_wrap_exceptions
    await fn()
  File "/zfsauton2/home/shrinivr/miniconda3/envs/py312/lib/python3.12/site-packages/wandb/sdk/lib/service/service_client.py", line 65, in _send_server_request
    await self._writer.drain()
  File "/zfsauton2/home/shrinivr/miniconda3/envs/py312/lib/python3.12/asyncio/streams.py", line 392, in drain
    await self._protocol._drain_helper()
  File "/zfsauton2/home/shrinivr/miniconda3/envs/py312/lib/python3.12/asyncio/streams.py", line 166, in _drain_helper
    raise ConnectionResetError('Connection lost')
ConnectionResetError: Connection lost
2025-09-01 13:09:08,480 ERROR   wandb-AsyncioManager-main:345772 [asyncio_manager.py:fn_wrap_exceptions():183] Uncaught exception in run_soon callback.
Traceback (most recent call last):
  File "/zfsauton2/home/shrinivr/miniconda3/envs/py312/lib/python3.12/site-packages/wandb/sdk/lib/asyncio_manager.py", line 181, in fn_wrap_exceptions
    await fn()
  File "/zfsauton2/home/shrinivr/miniconda3/envs/py312/lib/python3.12/site-packages/wandb/sdk/lib/service/service_client.py", line 65, in _send_server_request
    await self._writer.drain()
  File "/zfsauton2/home/shrinivr/miniconda3/envs/py312/lib/python3.12/asyncio/streams.py", line 392, in drain
    await self._protocol._drain_helper()
  File "/zfsauton2/home/shrinivr/miniconda3/envs/py312/lib/python3.12/asyncio/streams.py", line 166, in _drain_helper
    raise ConnectionResetError('Connection lost')
ConnectionResetError: Connection lost
2025-09-01 13:09:08,480 ERROR   wandb-AsyncioManager-main:345772 [asyncio_manager.py:fn_wrap_exceptions():183] Uncaught exception in run_soon callback.
Traceback (most recent call last):
  File "/zfsauton2/home/shrinivr/miniconda3/envs/py312/lib/python3.12/site-packages/wandb/sdk/lib/asyncio_manager.py", line 181, in fn_wrap_exceptions
    await fn()
  File "/zfsauton2/home/shrinivr/miniconda3/envs/py312/lib/python3.12/site-packages/wandb/sdk/lib/service/service_client.py", line 65, in _send_server_request
    await self._writer.drain()
  File "/zfsauton2/home/shrinivr/miniconda3/envs/py312/lib/python3.12/asyncio/streams.py", line 392, in drain
    await self._protocol._drain_helper()
  File "/zfsauton2/home/shrinivr/miniconda3/envs/py312/lib/python3.12/asyncio/streams.py", line 166, in _drain_helper
    raise ConnectionResetError('Connection lost')
ConnectionResetError: Connection lost
2025-09-01 13:09:08,503 ERROR   wandb-AsyncioManager-main:345772 [asyncio_manager.py:fn_wrap_exceptions():183] Uncaught exception in run_soon callback.
Traceback (most recent call last):
  File "/zfsauton2/home/shrinivr/miniconda3/envs/py312/lib/python3.12/site-packages/wandb/sdk/lib/asyncio_manager.py", line 181, in fn_wrap_exceptions
    await fn()
  File "/zfsauton2/home/shrinivr/miniconda3/envs/py312/lib/python3.12/site-packages/wandb/sdk/lib/service/service_client.py", line 65, in _send_server_request
    await self._writer.drain()
  File "/zfsauton2/home/shrinivr/miniconda3/envs/py312/lib/python3.12/asyncio/streams.py", line 392, in drain
    await self._protocol._drain_helper()
  File "/zfsauton2/home/shrinivr/miniconda3/envs/py312/lib/python3.12/asyncio/streams.py", line 166, in _drain_helper
    raise ConnectionResetError('Connection lost')
ConnectionResetError: Connection lost
2025-09-01 13:09:08,504 ERROR   wandb-AsyncioManager-main:345772 [asyncio_manager.py:fn_wrap_exceptions():183] Uncaught exception in run_soon callback.
Traceback (most recent call last):
  File "/zfsauton2/home/shrinivr/miniconda3/envs/py312/lib/python3.12/site-packages/wandb/sdk/lib/asyncio_manager.py", line 181, in fn_wrap_exceptions
    await fn()
  File "/zfsauton2/home/shrinivr/miniconda3/envs/py312/lib/python3.12/site-packages/wandb/sdk/lib/service/service_client.py", line 65, in _send_server_request
    await self._writer.drain()
  File "/zfsauton2/home/shrinivr/miniconda3/envs/py312/lib/python3.12/asyncio/streams.py", line 392, in drain
    await self._protocol._drain_helper()
  File "/zfsauton2/home/shrinivr/miniconda3/envs/py312/lib/python3.12/asyncio/streams.py", line 166, in _drain_helper
    raise ConnectionResetError('Connection lost')
ConnectionResetError: Connection lost
2025-09-01 13:09:08,504 ERROR   wandb-AsyncioManager-main:345772 [asyncio_manager.py:fn_wrap_exceptions():183] Uncaught exception in run_soon callback.
Traceback (most recent call last):
  File "/zfsauton2/home/shrinivr/miniconda3/envs/py312/lib/python3.12/site-packages/wandb/sdk/lib/asyncio_manager.py", line 181, in fn_wrap_exceptions
    await fn()
  File "/zfsauton2/home/shrinivr/miniconda3/envs/py312/lib/python3.12/site-packages/wandb/sdk/lib/service/service_client.py", line 65, in _send_server_request
    await self._writer.drain()
  File "/zfsauton2/home/shrinivr/miniconda3/envs/py312/lib/python3.12/asyncio/streams.py", line 392, in drain
    await self._protocol._drain_helper()
  File "/zfsauton2/home/shrinivr/miniconda3/envs/py312/lib/python3.12/asyncio/streams.py", line 166, in _drain_helper
    raise ConnectionResetError('Connection lost')
ConnectionResetError: Connection lost
2025-09-01 13:09:08,505 ERROR   wandb-AsyncioManager-main:345772 [asyncio_manager.py:fn_wrap_exceptions():183] Uncaught exception in run_soon callback.
Traceback (most recent call last):
  File "/zfsauton2/home/shrinivr/miniconda3/envs/py312/lib/python3.12/site-packages/wandb/sdk/lib/asyncio_manager.py", line 181, in fn_wrap_exceptions
    await fn()
  File "/zfsauton2/home/shrinivr/miniconda3/envs/py312/lib/python3.12/site-packages/wandb/sdk/lib/service/service_client.py", line 65, in _send_server_request
    await self._writer.drain()
  File "/zfsauton2/home/shrinivr/miniconda3/envs/py312/lib/python3.12/asyncio/streams.py", line 392, in drain
    await self._protocol._drain_helper()
  File "/zfsauton2/home/shrinivr/miniconda3/envs/py312/lib/python3.12/asyncio/streams.py", line 166, in _drain_helper
    raise ConnectionResetError('Connection lost')
ConnectionResetError: Connection lost
2025-09-01 13:09:08,505 ERROR   wandb-AsyncioManager-main:345772 [asyncio_manager.py:fn_wrap_exceptions():183] Uncaught exception in run_soon callback.
Traceback (most recent call last):
  File "/zfsauton2/home/shrinivr/miniconda3/envs/py312/lib/python3.12/site-packages/wandb/sdk/lib/asyncio_manager.py", line 181, in fn_wrap_exceptions
    await fn()
  File "/zfsauton2/home/shrinivr/miniconda3/envs/py312/lib/python3.12/site-packages/wandb/sdk/lib/service/service_client.py", line 65, in _send_server_request
    await self._writer.drain()
  File "/zfsauton2/home/shrinivr/miniconda3/envs/py312/lib/python3.12/asyncio/streams.py", line 392, in drain
    await self._protocol._drain_helper()
  File "/zfsauton2/home/shrinivr/miniconda3/envs/py312/lib/python3.12/asyncio/streams.py", line 166, in _drain_helper
    raise ConnectionResetError('Connection lost')
ConnectionResetError: Connection lost
2025-09-01 13:09:08,508 ERROR   wandb-AsyncioManager-main:345772 [asyncio_manager.py:fn_wrap_exceptions():183] Uncaught exception in run_soon callback.
Traceback (most recent call last):
  File "/zfsauton2/home/shrinivr/miniconda3/envs/py312/lib/python3.12/site-packages/wandb/sdk/lib/asyncio_manager.py", line 181, in fn_wrap_exceptions
    await fn()
  File "/zfsauton2/home/shrinivr/miniconda3/envs/py312/lib/python3.12/site-packages/wandb/sdk/lib/service/service_client.py", line 65, in _send_server_request
    await self._writer.drain()
  File "/zfsauton2/home/shrinivr/miniconda3/envs/py312/lib/python3.12/asyncio/streams.py", line 392, in drain
    await self._protocol._drain_helper()
  File "/zfsauton2/home/shrinivr/miniconda3/envs/py312/lib/python3.12/asyncio/streams.py", line 166, in _drain_helper
    raise ConnectionResetError('Connection lost')
ConnectionResetError: Connection lost
2025-09-01 13:09:08,509 ERROR   wandb-AsyncioManager-main:345772 [asyncio_manager.py:fn_wrap_exceptions():183] Uncaught exception in run_soon callback.
Traceback (most recent call last):
  File "/zfsauton2/home/shrinivr/miniconda3/envs/py312/lib/python3.12/site-packages/wandb/sdk/lib/asyncio_manager.py", line 181, in fn_wrap_exceptions
    await fn()
  File "/zfsauton2/home/shrinivr/miniconda3/envs/py312/lib/python3.12/site-packages/wandb/sdk/lib/service/service_client.py", line 65, in _send_server_request
    await self._writer.drain()
  File "/zfsauton2/home/shrinivr/miniconda3/envs/py312/lib/python3.12/asyncio/streams.py", line 392, in drain
    await self._protocol._drain_helper()
  File "/zfsauton2/home/shrinivr/miniconda3/envs/py312/lib/python3.12/asyncio/streams.py", line 166, in _drain_helper
    raise ConnectionResetError('Connection lost')
ConnectionResetError: Connection lost
